Workbook

Sheet Rules
B1: CMES4 v2 rules
B3: COLOURS
B4: Yellow cells | C4: You type here.
B5: Grey cells | C5: Formulas. Don't type over them.
B6: Example | C6: The ticket opens with a worked example (a long on 12 Oct). Overwrite the yellow cells.
B7: RULES
B8: 1. Windows | C8: New setups only 09:45-11:30 and 14:00-15:30 New York time (Dublin: see the ticket tab). Flat by 15:55 New York.
B9: 2. Trend | C9: The last three completed 15-min bars each made a higher high AND a higher low than the bar before (long). Lower highs and lower lows for a short. One wording only: three bars, two comparisons.
B10: 3. Pullback | C10: Within the next three 5-min bars, one bar's low goes below the previous bar's low (long) or its high above the previous bar's high (short). Equal does not count.
B11: 4. Confirmation | C11: The very next 5-min bar closes above the pullback bar's close (long) or below it (short).
B12: 5. Entry | C12: Stop order one tick beyond the confirming bar's high (long) or low (short). Cancel if not filled in 10 minutes.
B13: 6. Stop-loss | C13: One tick beyond the pullback bar's low (long) or high (short). Skip the trade if that is under 2 or over 12 ES points from the entry.
B14: 7. Exits | C14: Half the contracts at +2R with a limit order. When it fills, move the stop on the rest to the entry price, then after each 5-min bar raise it to one tick under the lowest low of the last three bars (long). If +2R is not reached within 60 minutes of the fill, exit everything at market.
B15: 8. Size | C15: Risk 0.5% of the balance per trade, 1% after the backtest go/no-go passes. Never more contracts than the margin allows. Max 3 trades a day; stop after 2 losers.
B16: 9. Log | C16: Every setup goes in Decisions, taken or not, with the bar times. Trades go in Trades with the ticket's numbers.
B17: WHY THESE CHANGES
B18: Small targets | C18: CMES4 v1's 2R target is about 8 ES points: at most 1.4% of the account per perfect trade, even at the margin limit.
B19: Costs | C19: With a 4-point stop, commission and two ticks of slippage cost about 0.12R a trade. v2's median stop is about 7 points, which roughly halves that.
B20: Lunch | C20: The 6 Oct checks were all 11:15-12:45 New York, the quietest part of the day.
B21: Ambiguity | C21: D001: the 3-bar and 4-bar wordings disagreed. v2 keeps one.
B22: Entry | C22: T003 was sold before the bounce and confirmation. A stop order placed from this ticket cannot jump the gun.

Sheet CMES4 v2 ticket
B1: CMES4 v2 order ticket
B2: Fill the yellow cells once the confirming 5-minute bar has closed. Grey cells are formulas. Place the order only if the verdict says GO.
B4: SETUP | F4: CONTRACTS (edit margin to match CQG)
B5: Contract | C5: ES | F5: Contract | G5: $ per point | H5: Tick | I5: Margin ($) | J5: Min stop (pts) | K5: Max stop (pts)
B6: Direction | C6: Long | F6: ES | G6: 50 | H6: 0.25 | I6: 28600 | J6: 2 | K6: 12
B7: Date | C7: 46307 | F7: MES | G7: 5 | H7: 0.25 | I7: 2860 | J7: 2 | K7: 12
B8: Confirming bar closed at (Dublin time) | C8: 0.63888889 | F8: NQ | G8: 20 | H8: 0.25 | J8: 8 | K8: 48
B9: Account balance from CQG ($) | C9: 1001395 | F9: MNQ | G9: 2 | H9: 0.25 | J9: 8 | K9: 48
B10: Risk per trade (% of balance) | C10: 0.005
B11: Trades already taken today | C11: 0 | F11: Commission per side ($) | G11: 2.5
B12: Losing trades today | C12: 0
B13: Scheduled news in the next 15 minutes? | C13: No
F14: TRADING WINDOWS (Dublin time)
B15: BARS (read off the 5-minute chart) | F15: Dates | G15: Morning | H15: Afternoon | I15: Flat by | J15: Clock
B16: Pullback bar high | C16: 7843 | F16: 9-23 Oct | G16: 14:45-16:30 | H16: 19:00-20:30 | I16: 20:55 | J16: ET + 5h
B17: Pullback bar low | C17: 7838 | F17: 26-30 Oct | G17: 13:45-15:30 | H17: 18:00-19:30 | I17: 19:55 | J17: ET + 4h
B18: Pullback bar close | C18: 7839.5 | F18: Wed 28 Oct | G18: 13:45-15:30 | H18: none (FOMC 18:00) | I18: 17:55 | J18: ET + 4h
B19: Confirming bar high | C19: 7845.5 | F19: Fri 30 Oct | G19: 13:45-15:30 | H19: none | I19: 19:00 team cut-off | J19: ET + 4h
B20: Confirming bar low | C20: 7839.25
B21: Confirming bar close | C21: 7844.75 | F21: Windows are 09:45-11:30 and 14:00-15:30 New York time. The check above allows the confirming bar to close up to 20 minutes after a window ends.
B23: ORDER (bracket: stop entry + stop-loss + half at +2R)
B24: Entry: stop order at | C24: =IF($C$6="Long",$C$19+INDEX($H$6:$H$9,MATCH($C$5,$F$6:$F$9,0)),$C$20-INDEX($H$6:$H$9,MATCH($C$5,$F$6:$F$9,0))) -> 7845.75
B25: Stop-loss at | C25: =IF($C$6="Long",$C$17-INDEX($H$6:$H$9,MATCH($C$5,$F$6:$F$9,0)),$C$16+INDEX($H$6:$H$9,MATCH($C$5,$F$6:$F$9,0))) -> 7837.75
B26: Risk per contract (points) | C26: =ABS(C24-C25) -> 8
B27: Target for half the contracts (+2R) at | C27: =IF($C$6="Long",C24+2*C26,C24-2*C26) -> 7861.75
B28: Contracts by risk budget | C28: =IFERROR(ROUNDDOWN($C$9*$C$10/(C26*INDEX($G$6:$G$9,MATCH($C$5,$F$6:$F$9,0))+2*$G$11),0),0) -> 12
B29: Contracts the margin allows | C29: =IFERROR(IF(INDEX($I$6:$I$9,MATCH($C$5,$F$6:$F$9,0))>0,ROUNDDOWN($C$9/INDEX($I$6:$I$9,MATCH($C$5,$F$6:$F$9,0)),0),C28),0) -> 35
B30: CONTRACTS TO TRADE | C30: =MAX(0,MIN(C28,C29)) -> 12
B31: of which: limit at +2R | C31: =ROUNDDOWN(C30/2,0) -> 6
B32: of which: runner, trailed | C32: =C30-C31 -> 6
B33: $ at risk if stopped (incl. commission) | C33: =C30*(C26*INDEX($G$6:$G$9,MATCH($C$5,$F$6:$F$9,0))+2*$G$11) -> 4860
B34: % of balance at risk | C34: =IFERROR(C33/$C$9,0) -> 0.0048532297
B35: Cancel the entry if not filled by (Dublin) | C35: =$C$8+TIME(0,10,0) -> 0.64583333
B36: Flat by (Dublin) | C36: =IF($C$7=DATE(2026,10,28),TIME(17,55,0),IF($C$7=DATE(2026,10,30),TIME(19,0,0),IF($C$7>=DATE(2026,10,26),TIME(19,55,0),TIME(20,55,0)))) -> 0.87152778
B38: CHECKS
B39: Confirming close beyond the pullback bar's close | C39: =IF($C$6="Long",$C$21>$C$18,$C$21<$C$18) -> TRUE
B40: Prices make sense (stop below the entry for a long) | C40: =IF($C$6="Long",C25<C24,C25>C24) -> TRUE
B41: Stop inside the band for this contract | C41: =AND(C26>=INDEX($J$6:$J$9,MATCH($C$5,$F$6:$F$9,0)),C26<=INDEX($K$6:$K$9,MATCH($C$5,$F$6:$F$9,0))) -> TRUE
B42: Inside a trading window (see table) | C42: =OR(AND($C$8>=IF($C$7<DATE(2026,10,26),TIME(14,50,0),TIME(13,50,0)),$C$8<=IF($C$7<DATE(2026,10,26),TIME(16,50,0),TIME(15,50,0))),AND($C$8>=IF($C$7<DATE(2026,10,26),TIME(19,5,0),TIME(18,5,0)),$C$8<=IF($C$7<DATE(2026,10,26),TIME(20,50,0),TIME(19,50,0)),$C$7<>DATE(2026,10,28),$C$7<>DATE(2026,10,30))) -> TRUE
B43: Fewer than 3 trades and 2 losers today | C43: =AND($C$11<3,$C$12<2) -> TRUE
...

Sheet Sizing table
B1: ES contracts by stop distance
B2: Uses the balance and ES margin from the ticket tab. Commission is included in the risk per contract. The margin cap binds first for stops under about 7 points at 1% risk.
B4: Stop (ES pts) | C4: Risk per ES ($) | D4: ES at 0.5% | E4: $ at risk | F4: ES at 1% (capped) | G4: $ at risk | H4: MES at 0.5%
B5: 2 | C5: =B5*50+2*'CMES4 v2 ticket'!$G$11 -> 105 | D5: =MIN(ROUNDDOWN('CMES4 v2 ticket'!$C$9*0.005/C5,0),ROUNDDOWN('CMES4 v2 ticket'!$C$9/'CMES4 v2 ticket'!$I$6,0)) -> 35 | E5: =D5*C5 -> 3675 | F5: =MIN(ROUNDDOWN('CMES4 v2 ticket'!$C$9*0.01/C5,0),ROUNDDOWN('CMES4 v2 ticket'!$C$9/'CMES4 v2 ticket'!$I$6,0)) -> 35 | G5: =F5*C5 -> 3675 | H5: =MIN(ROUNDDOWN('CMES4 v2 ticket'!$C$9*0.005/(B5*5+2*'CMES4 v2 ticket'!$G$11),0),ROUNDDOWN('CMES4 v2 ticket'!$C$9/'CMES4 v2 ticket'!$I$7,0)) -> 333
B6: 2.5 | C6: =B6*50+2*'CMES4 v2 ticket'!$G$11 -> 130 | D6: =MIN(ROUNDDOWN('CMES4 v2 ticket'!$C$9*0.005/C6,0),ROUNDDOWN('CMES4 v2 ticket'!$C$9/'CMES4 v2 ticket'!$I$6,0)) -> 35 | E6: =D6*C6 -> 4550 | F6: =MIN(ROUNDDOWN('CMES4 v2 ticket'!$C$9*0.01/C6,0),ROUNDDOWN('CMES4 v2 ticket'!$C$9/'CMES4 v2 ticket'!$I$6,0)) -> 35 | G6: =F6*C6 -> 4550 | H6: =MIN(ROUNDDOWN('CMES4 v2 ticket'!$C$9*0.005/(B6*5+2*'CMES4 v2 ticket'!$G$11),0),ROUNDDOWN('CMES4 v2 ticket'!$C$9/'CMES4 v2 ticket'!$I$7,0)) -> 286
B7: 3 | C7: =B7*50+2*'CMES4 v2 ticket'!$G$11 -> 155 | D7: =MIN(ROUNDDOWN('CMES4 v2 ticket'!$C$9*0.005/C7,0),ROUNDDOWN('CMES4 v2 ticket'!$C$9/'CMES4 v2 ticket'!$I$6,0)) -> 32 | E7: =D7*C7 -> 4960 | F7: =MIN(ROUNDDOWN('CMES4 v2 ticket'!$C$9*0.01/C7,0),ROUNDDOWN('CMES4 v2 ticket'!$C$9/'CMES4 v2 ticket'!$I$6,0)) -> 35 | G7: =F7*C7 -> 5425 | H7: =MIN(ROUNDDOWN('CMES4 v2 ticket'!$C$9*0.005/(B7*5+2*'CMES4 v2 ticket'!$G$11),0),ROUNDDOWN('CMES4 v2 ticket'!$C$9/'CMES4 v2 ticket'!$I$7,0)) -> 250
B8: 3.5 | C8: =B8*50+2*'CMES4 v2 ticket'!$G$11 -> 180 | D8: =MIN(ROUNDDOWN('CMES4 v2 ticket'!$C$9*0.005/C8,0),ROUNDDOWN('CMES4 v2 ticket'!$C$9/'CMES4 v2 ticket'!$I$6,0)) -> 27 | E8: =D8*C8 -> 4860 | F8: =MIN(ROUNDDOWN('CMES4 v2 ticket'!$C$9*0.01/C8,0),ROUNDDOWN('CMES4 v2 ticket'!$C$9/'CMES4 v2 ticket'!$I$6,0)) -> 35 | G8: =F8*C8 -> 6300 | H8: =MIN(ROUNDDOWN('CMES4 v2 ticket'!$C$9*0.005/(B8*5+2*'CMES4 v2 ticket'!$G$11),0),ROUNDDOWN('CMES4 v2 ticket'!$C$9/'CMES4 v2 ticket'!$I$7,0)) -> 222
B9: 4 | C9: =B9*50+2*'CMES4 v2 ticket'!$G$11 -> 205 | D9: =MIN(ROUNDDOWN('CMES4 v2 ticket'!$C$9*0.005/C9,0),ROUNDDOWN('CMES4 v2 ticket'!$C$9/'CMES4 v2 ticket'!$I$6,0)) -> 24 | E9: =D9*C9 -> 4920 | F9: =MIN(ROUNDDOWN('CMES4 v2 ticket'!$C$9*0.01/C9,0),ROUNDDOWN('CMES4 v2 ticket'!$C$9/'CMES4 v2 ticket'!$I$6,0)) -> 35 | G9: =F9*C9 -> 7175 | H9: =MIN(ROUNDDOWN('CMES4 v2 ticket'!$C$9*0.005/(B9*5+2*'CMES4 v2 ticket'!$G$11),0),ROUNDDOWN('CMES4 v2 ticket'!$C$9/'CMES4 v2 ticket'!$I$7,0)) -> 200
B10: 4.5 | C10: =B10*50+2*'CMES4 v2 ticket'!$G$11 -> 230 | D10: =MIN(ROUNDDOWN('CMES4 v2 ticket'!$C$9*0.005/C10,0),ROUNDDOWN('CMES4 v2 ticket'!$C$9/'CMES4 v2 ticket'!$I$6,0)) -> 21 | E10: =D10*C10 -> 4830 | F10: =MIN(ROUNDDOWN('CMES4 v2 ticket'!$C$9*0.01/C10,0),ROUNDDOWN('CMES4 v2 ticket'!$C$9/'CMES4 v2 ticket'!$I$6,0)) -> 35 | G10: =F10*C10 -> 8050 | H10: =MIN(ROUNDDOWN('CMES4 v2 ticket'!$C$9*0.005/(B10*5+2*'CMES4 v2 ticket'!$G$11),0),ROUNDDOWN('CMES4 v2 ticket'!$C$9/'CMES4 v2 ticket'!$I$7,0)) -> 182
B11: 5 | C11: =B11*50+2*'CMES4 v2 ticket'!$G$11 -> 255 | D11: =MIN(ROUNDDOWN('CMES4 v2 ticket'!$C$9*0.005/C11,0),ROUNDDOWN('CMES4 v2 ticket'!$C$9/'CMES4 v2 ticket'!$I$6,0)) -> 19 | E11: =D11*C11 -> 4845 | F11: =MIN(ROUNDDOWN('CMES4 v2 ticket'!$C$9*0.01/C11,0),ROUNDDOWN('CMES4 v2 ticket'!$C$9/'CMES4 v2 ticket'!$I$6,0)) -> 35 | G11: =F11*C11 -> 8925 | H11: =MIN(ROUNDDOWN('CMES4 v2 ticket'!$C$9*0.005/(B11*5+2*'CMES4 v2 ticket'!$G$11),0),ROUNDDOWN('CMES4 v2 ticket'!$C$9/'CMES4 v2 ticket'!$I$7,0)) -> 166
B12: 5.5 | C12: =B12*50+2*'CMES4 v2 ticket'!$G$11 -> 280 | D12: =MIN(ROUNDDOWN('CMES4 v2 ticket'!$C$9*0.005/C12,0),ROUNDDOWN('CMES4 v2 ticket'!$C$9/'CMES4 v2 ticket'!$I$6,0)) -> 17 | E12: =D12*C12 -> 4760 | F12: =MIN(ROUNDDOWN('CMES4 v2 ticket'!$C$9*0.01/C12,0),ROUNDDOWN('CMES4 v2 ticket'!$C$9/'CMES4 v2 ticket'!$I$6,0)) -> 35 | G12: =F12*C12 -> 9800 | H12: =MIN(ROUNDDOWN('CMES4 v2 ticket'!$C$9*0.005/(B12*5+2*'CMES4 v2 ticket'!$G$11),0),ROUNDDOWN('CMES4 v2 ticket'!$C$9/'CMES4 v2 ticket'!$I$7,0)) -> 154
B13: 6 | C13: =B13*50+2*'CMES4 v2 ticket'!$G$11 -> 305 | D13: =MIN(ROUNDDOWN('CMES4 v2 ticket'!$C$9*0.005/C13,0),ROUNDDOWN('CMES4 v2 ticket'!$C$9/'CMES4 v2 ticket'!$I$6,0)) -> 16 | E13: =D13*C13 -> 4880 | F13: =MIN(ROUNDDOWN('CMES4 v2 ticket'!$C$9*0.01/C13,0),ROUNDDOWN('CMES4 v2 ticket'!$C$9/'CMES4 v2 ticket'!$I$6,0)) -> 32 | G13: =F13*C13 -> 9760 | H13: =MIN(ROUNDDOWN('CMES4 v2 ticket'!$C$9*0.005/(B13*5+2*'CMES4 v2 ticket'!$G$11),0),ROUNDDOWN('CMES4 v2 ticket'!$C$9/'CMES4 v2 ticket'!$I$7,0)) -> 143
B14: 6.5 | C14: =B14*50+2*'CMES4 v2 ticket'!$G$11 -> 330 | D14: =MIN(ROUNDDOWN('CMES4 v2 ticket'!$C$9*0.005/C14,0),ROUNDDOWN('CMES4 v2 ticket'!$C$9/'CMES4 v2 ticket'!$I$6,0)) -> 15 | E14: =D14*C14 -> 4950 | F14: =MIN(ROUNDDOWN('CMES4 v2 ticket'!$C$9*0.01/C14,0),ROUNDDOWN('CMES4 v2 ticket'!$C$9/'CMES4 v2 ticket'!$I$6,0)) -> 30 | G14: =F14*C14 -> 9900 | H14: =MIN(ROUNDDOWN('CMES4 v2 ticket'!$C$9*0.005/(B14*5+2*'CMES4 v2 ticket'!$G$11),0),ROUNDDOWN('CMES4 v2 ticket'!$C$9/'CMES4 v2 ticket'!$I$7,0)) -> 133
B15: 7 | C15: =B15*50+2*'CMES4 v2 ticket'!$G$11 -> 355 | D15: =MIN(ROUNDDOWN('CMES4 v2 ticket'!$C$9*0.005/C15,0),ROUNDDOWN('CMES4 v2 ticket'!$C$9/'CMES4 v2 ticket'!$I$6,0)) -> 14 | E15: =D15*C15 -> 4970 | F15: =MIN(ROUNDDOWN('CMES4 v2 ticket'!$C$9*0.01/C15,0),ROUNDDOWN('CMES4 v2 ticket'!$C$9/'CMES4 v2 ticket'!$I$6,0)) -> 28 | G15: =F15*C15 -> 9940 | H15: =MIN(ROUNDDOWN('CMES4 v2 ticket'!$C$9*0.005/(B15*5+2*'CMES4 v2 ticket'!$G$11),0),ROUNDDOWN('CMES4 v2 ticket'!$C$9/'CMES4 v2 ticket'!$I$7,0)) -> 125
B16: 7.5 | C16: =B16*50+2*'CMES4 v2 ticket'!$G$11 -> 380 | D16: =MIN(ROUNDDOWN('CMES4 v2 ticket'!$C$9*0.005/C16,0),ROUNDDOWN('CMES4 v2 ticket'!$C$9/'CMES4 v2 ticket'!$I$6,0)) -> 13 | E16: =D16*C16 -> 4940 | F16: =MIN(ROUNDDOWN('CMES4 v2 ticket'!$C$9*0.01/C16,0),ROUNDDOWN('CMES4 v2 ticket'!$C$9/'CMES4 v2 ticket'!$I$6,0)) -> 26 | G16: =F16*C16 -> 9880 | H16: =MIN(ROUNDDOWN('CMES4 v2 ticket'!$C$9*0.005/(B16*5+2*'CMES4 v2 ticket'!$G$11),0),ROUNDDOWN('CMES4 v2 ticket'!$C$9/'CMES4 v2 ticket'!$I$7,0)) -> 117
... B25: 12 | C25: =B25*50+2*'CMES4 v2 ticket'!$G$11 -> 605 | D25: =MIN(ROUNDDOWN('CMES4 v2 ticket'!$C$9*0.005/C25,0),ROUNDDOWN('CMES4 v2 ticket'!$C$9/'CMES4 v2 ticket'!$I$6,0)) -> 8 | E25: =D25*C25 -> 4840 | F25: =MIN(ROUNDDOWN('CMES4 v2 ticket'!$C$9*0.01/C25,0),ROUNDDOWN('CMES4 v2 ticket'!$C$9/'CMES4 v2 ticket'!$I$6,0)) -> 16 | G25: =F25*C25 -> 9680 | H25: =MIN(ROUNDDOWN('CMES4 v2 ticket'!$C$9*0.005/(B25*5+2*'CMES4 v2 ticket'!$G$11),0),ROUNDDOWN('CMES4 v2 ticket'!$C$9/'CMES4 v2 ticket'!$I$7,0)) -> 77
